telegram.ext.updater - INFO - Received signal 2 (SIGINT), stopping...
root - INFO - Бот запускается
telegram.ext.updater - INFO - Received signal 2 (SIGINT), stopping...
telegram.ext.updater - WARNING - Exiting immediately!
2019-12-01 22:35:31,161 - INFO - Бот запускается
2019-12-01 22:36:10,308 - INFO - Received signal 2 (SIGINT), stopping...
2019-12-01 22:38:23,678 - INFO - Бот запускается
2019-12-01 22:38:42,871 - INFO - Received signal 2 (SIGINT), stopping...
2019-12-01 22:41:55,293 - INFO - Бот запускается
2019-12-01 22:41:59,331 - INFO - Received signal 2 (SIGINT), stopping...
2019-12-01 22:42:08,563 - WARNING - Exiting immediately!
2019-12-01 22:42:18,939 - INFO - Бот запускается
2019-12-01 22:42:23,456 - INFO - Вызван /start
2019-12-01 22:43:14,203 - INFO - Received signal 2 (SIGINT), stopping...
2019-12-01 22:43:20,286 - INFO - Бот запускается
2019-12-01 22:49:09,202 - INFO - Received signal 2 (SIGINT), stopping...
2019-12-01 22:49:13,937 - WARNING - Exiting immediately!
2019-12-01 22:49:17,609 - INFO - Бот запускается
2019-12-01 22:55:03,736 - INFO - Received signal 2 (SIGINT), stopping...
2019-12-01 22:55:12,065 - INFO - Бот запускается
2019-12-01 22:55:16,372 - ERROR - No error handlers are registered, logging exception.
Traceback (most recent call last):
  File "C:\Users\User\AppData\Local\Programs\Python\Python37\lib\site-packages\telegram\ext\dispatcher.py", line 372, in process_update
    handler.handle_update(update, self, check, context)
  File "C:\Users\User\AppData\Local\Programs\Python\Python37\lib\site-packages\telegram\ext\handler.py", line 120, in handle_update
    return self.callback(dispatcher.bot, update, **optional_args)
  File "C:\projects\lesson1\vitaliybot\bot.py", line 25, in talk_to_me
    update.message.chat.id, update.message.chat.message)
AttributeError: 'Chat' object has no attribute 'message'
2019-12-01 22:55:44,026 - ERROR - No error handlers are registered, logging exception.
Traceback (most recent call last):
  File "C:\Users\User\AppData\Local\Programs\Python\Python37\lib\site-packages\telegram\ext\dispatcher.py", line 372, in process_update
    handler.handle_update(update, self, check, context)
  File "C:\Users\User\AppData\Local\Programs\Python\Python37\lib\site-packages\telegram\ext\handler.py", line 120, in handle_update
    return self.callback(dispatcher.bot, update, **optional_args)
  File "C:\projects\lesson1\vitaliybot\bot.py", line 25, in talk_to_me
    update.message.chat.id, update.message.chat.message)
AttributeError: 'Chat' object has no attribute 'message'
2019-12-01 22:56:50,957 - INFO - Received signal 2 (SIGINT), stopping...
2019-12-01 22:58:06,076 - INFO - Бот запускается
2019-12-01 22:58:10,302 - INFO - User: vitaliypopkov, Chat id: 55831021, Message: Привет
2019-12-01 23:13:44,883 - INFO - Received signal 2 (SIGINT), stopping...
2019-12-01 23:36:33,731 - INFO - Бот запускается
2019-12-02 00:13:07,724 - INFO - Бот запускается
2019-12-02 00:13:20,624 - ERROR - No error handlers are registered, logging exception.
Traceback (most recent call last):
  File "C:\Users\User\AppData\Local\Programs\Python\Python37\lib\site-packages\telegram\ext\dispatcher.py", line 372, in process_update
    handler.handle_update(update, self, check, context)
  File "C:\Users\User\AppData\Local\Programs\Python\Python37\lib\site-packages\telegram\ext\handler.py", line 120, in handle_update
    return self.callback(dispatcher.bot, update, **optional_args)
TypeError: planet() takes 1 positional argument but 2 were given
2019-12-02 00:13:39,154 - INFO - User: vitaliypopkov, Chat id: 55831021, Message: planet
2019-12-02 00:14:35,861 - ERROR - No error handlers are registered, logging exception.
Traceback (most recent call last):
  File "C:\Users\User\AppData\Local\Programs\Python\Python37\lib\site-packages\telegram\ext\dispatcher.py", line 372, in process_update
    handler.handle_update(update, self, check, context)
  File "C:\Users\User\AppData\Local\Programs\Python\Python37\lib\site-packages\telegram\ext\handler.py", line 120, in handle_update
    return self.callback(dispatcher.bot, update, **optional_args)
TypeError: planet() takes 1 positional argument but 2 were given
2019-12-02 00:14:38,217 - ERROR - No error handlers are registered, logging exception.
Traceback (most recent call last):
  File "C:\Users\User\AppData\Local\Programs\Python\Python37\lib\site-packages\telegram\ext\dispatcher.py", line 372, in process_update
    handler.handle_update(update, self, check, context)
  File "C:\Users\User\AppData\Local\Programs\Python\Python37\lib\site-packages\telegram\ext\handler.py", line 120, in handle_update
    return self.callback(dispatcher.bot, update, **optional_args)
TypeError: planet() takes 1 positional argument but 2 were given
2019-12-02 00:15:52,300 - INFO - Received signal 2 (SIGINT), stopping...
2019-12-02 00:16:03,892 - INFO - Бот запускается
2019-12-02 00:16:12,351 - ERROR - No error handlers are registered, logging exception.
Traceback (most recent call last):
  File "C:\Users\User\AppData\Local\Programs\Python\Python37\lib\site-packages\telegram\ext\dispatcher.py", line 372, in process_update
    handler.handle_update(update, self, check, context)
  File "C:\Users\User\AppData\Local\Programs\Python\Python37\lib\site-packages\telegram\ext\handler.py", line 120, in handle_update
    return self.callback(dispatcher.bot, update, **optional_args)
TypeError: planet() takes 1 positional argument but 2 were given
2019-12-02 00:16:36,406 - INFO - User: vitaliypopkov, Chat id: 55831021, Message: start
2019-12-02 00:16:42,371 - INFO - Вызван /start
2019-12-02 00:16:42,372 - ERROR - No error handlers are registered, logging exception.
Traceback (most recent call last):
  File "C:\Users\User\AppData\Local\Programs\Python\Python37\lib\site-packages\telegram\ext\dispatcher.py", line 372, in process_update
    handler.handle_update(update, self, check, context)
  File "C:\Users\User\AppData\Local\Programs\Python\Python37\lib\site-packages\telegram\ext\handler.py", line 120, in handle_update
    return self.callback(dispatcher.bot, update, **optional_args)
  File "C:\projects\lesson1\vitaliybot\bot.py", line 20, in greet_user
    update.message.reply_text(text)
AttributeError: 'NoneType' object has no attribute 'reply_text'
2019-12-02 00:16:48,034 - INFO - Вызван /start
2019-12-02 00:16:52,109 - ERROR - No error handlers are registered, logging exception.
Traceback (most recent call last):
  File "C:\Users\User\AppData\Local\Programs\Python\Python37\lib\site-packages\telegram\ext\dispatcher.py", line 372, in process_update
    handler.handle_update(update, self, check, context)
  File "C:\Users\User\AppData\Local\Programs\Python\Python37\lib\site-packages\telegram\ext\handler.py", line 120, in handle_update
    return self.callback(dispatcher.bot, update, **optional_args)
TypeError: planet() takes 1 positional argument but 2 were given
2019-12-02 00:18:20,355 - INFO - Received signal 2 (SIGINT), stopping...
2019-12-02 00:18:26,323 - INFO - Бот запускается
2019-12-02 00:19:07,296 - INFO - Received signal 2 (SIGINT), stopping...
2019-12-02 00:19:20,284 - INFO - Бот запускается
2019-12-02 00:19:36,270 - INFO - User: vitaliypopkov, Chat id: 55831021, Message: Mars
2019-12-02 00:22:42,306 - INFO - Received signal 2 (SIGINT), stopping...
2019-12-02 00:22:45,556 - INFO - Бот запускается
2019-12-02 00:22:57,316 - INFO - User: vitaliypopkov, Chat id: 55831021, Message: Mars
2019-12-02 00:23:23,175 - INFO - Received signal 2 (SIGINT), stopping...
2019-12-02 00:23:29,622 - INFO - Бот запускается
2019-12-02 00:23:36,386 - INFO - User: vitaliypopkov, Chat id: 55831021, Message: Mars
2019-12-02 00:24:44,610 - INFO - Received signal 2 (SIGINT), stopping...
2019-12-02 00:24:49,174 - INFO - Бот запускается
2019-12-02 00:25:18,441 - INFO - Бот запускается
2019-12-02 00:27:22,538 - INFO - Received signal 2 (SIGINT), stopping...
2019-12-02 00:27:26,024 - INFO - Бот запускается
2019-12-02 00:31:34,482 - INFO - Received signal 2 (SIGINT), stopping...
2019-12-02 00:31:40,594 - INFO - Бот запускается
2019-12-02 01:22:44,159 - INFO - Received signal 2 (SIGINT), stopping...
2019-12-02 01:22:52,582 - INFO - Бот запускается
2019-12-02 01:29:56,592 - INFO - Received signal 2 (SIGINT), stopping...
2019-12-02 01:34:41,784 - INFO - Бот запускается
2019-12-02 01:34:49,258 - ERROR - No error handlers are registered, logging exception.
Traceback (most recent call last):
  File "C:\Users\User\AppData\Local\Programs\Python\Python37\lib\site-packages\telegram\ext\dispatcher.py", line 372, in process_update
    handler.handle_update(update, self, check, context)
  File "C:\Users\User\AppData\Local\Programs\Python\Python37\lib\site-packages\telegram\ext\handler.py", line 120, in handle_update
    return self.callback(dispatcher.bot, update, **optional_args)
  File "C:\projects\lesson1\vitaliybot\bot.py", line 20, in planet
    mars = ephem.Mars("qusetions_date")
ValueError: your date string  does not look like a year/month/day optionally followed by hours:minutes:seconds
2019-12-02 01:35:57,178 - INFO - Received signal 2 (SIGINT), stopping...
2019-12-02 01:36:01,942 - INFO - Бот запускается
2019-12-02 01:36:07,507 - ERROR - No error handlers are registered, logging exception.
Traceback (most recent call last):
  File "C:\Users\User\AppData\Local\Programs\Python\Python37\lib\site-packages\telegram\ext\dispatcher.py", line 372, in process_update
    handler.handle_update(update, self, check, context)
  File "C:\Users\User\AppData\Local\Programs\Python\Python37\lib\site-packages\telegram\ext\handler.py", line 120, in handle_update
    return self.callback(dispatcher.bot, update, **optional_args)
  File "C:\projects\lesson1\vitaliybot\bot.py", line 20, in planet
    mars = ephem.Mars("qusetions_date")
ValueError: your date string  does not look like a year/month/day optionally followed by hours:minutes:seconds
2019-12-02 01:36:47,617 - INFO - Received signal 2 (SIGINT), stopping...
2019-12-02 01:36:50,006 - INFO - Бот запускается
2019-12-02 01:36:58,355 - ERROR - No error handlers are registered, logging exception.
Traceback (most recent call last):
  File "C:\Users\User\AppData\Local\Programs\Python\Python37\lib\site-packages\telegram\ext\dispatcher.py", line 372, in process_update
    handler.handle_update(update, self, check, context)
  File "C:\Users\User\AppData\Local\Programs\Python\Python37\lib\site-packages\telegram\ext\handler.py", line 120, in handle_update
    return self.callback(dispatcher.bot, update, **optional_args)
  File "C:\projects\lesson1\vitaliybot\bot.py", line 21, in planet
    mars = ephem.Mars("qusetions_date")
ValueError: your date string  does not look like a year/month/day optionally followed by hours:minutes:seconds
2019-12-02 01:37:54,904 - INFO - Received signal 2 (SIGINT), stopping...
2019-12-02 01:37:59,684 - INFO - Бот запускается
2019-12-02 01:38:52,248 - INFO - Received signal 2 (SIGINT), stopping...
2019-12-02 01:39:03,194 - INFO - Бот запускается
2019-12-02 01:51:44,791 - INFO - Received signal 2 (SIGINT), stopping...
2019-12-02 01:51:48,748 - INFO - Бот запускается
2019-12-02 01:51:55,187 - ERROR - No error handlers are registered, logging exception.
Traceback (most recent call last):
  File "C:\Users\User\AppData\Local\Programs\Python\Python37\lib\site-packages\telegram\ext\dispatcher.py", line 372, in process_update
    handler.handle_update(update, self, check, context)
  File "C:\Users\User\AppData\Local\Programs\Python\Python37\lib\site-packages\telegram\ext\handler.py", line 120, in handle_update
    return self.callback(dispatcher.bot, update, **optional_args)
  File "C:\projects\lesson1\vitaliybot\bot.py", line 19, in planet
    mars = ephem.update.message.text.split()[1](update.message.date)
AttributeError: module 'ephem' has no attribute 'update'
2019-12-02 01:52:38,635 - INFO - Received signal 2 (SIGINT), stopping...
2019-12-02 01:52:48,204 - INFO - Бот запускается
2019-12-02 01:52:51,510 - ERROR - No error handlers are registered, logging exception.
Traceback (most recent call last):
  File "C:\Users\User\AppData\Local\Programs\Python\Python37\lib\site-packages\telegram\ext\dispatcher.py", line 372, in process_update
    handler.handle_update(update, self, check, context)
  File "C:\Users\User\AppData\Local\Programs\Python\Python37\lib\site-packages\telegram\ext\handler.py", line 120, in handle_update
    return self.callback(dispatcher.bot, update, **optional_args)
  File "C:\projects\lesson1\vitaliybot\bot.py", line 19, in planet
    mars = ephem.planet_name(update.message.date)
AttributeError: module 'ephem' has no attribute 'planet_name'
2019-12-02 01:56:36,806 - INFO - Received signal 2 (SIGINT), stopping...
2019-12-02 01:56:46,071 - INFO - Бот запускается
2019-12-02 01:57:30,934 - INFO - Received signal 2 (SIGINT), stopping...
2019-12-02 01:57:33,774 - INFO - Бот запускается
2019-12-02 01:57:42,500 - ERROR - No error handlers are registered, logging exception.
Traceback (most recent call last):
  File "C:\Users\User\AppData\Local\Programs\Python\Python37\lib\site-packages\telegram\ext\dispatcher.py", line 372, in process_update
    handler.handle_update(update, self, check, context)
  File "C:\Users\User\AppData\Local\Programs\Python\Python37\lib\site-packages\telegram\ext\handler.py", line 120, in handle_update
    return self.callback(dispatcher.bot, update, **optional_args)
TypeError: talk_to_me() got an unexpected keyword argument 'update_queue'
2019-12-02 02:07:35,080 - ERROR - No error handlers are registered, logging exception.
Traceback (most recent call last):
  File "C:\Users\User\AppData\Local\Programs\Python\Python37\lib\site-packages\telegram\ext\dispatcher.py", line 372, in process_update
    handler.handle_update(update, self, check, context)
  File "C:\Users\User\AppData\Local\Programs\Python\Python37\lib\site-packages\telegram\ext\handler.py", line 120, in handle_update
    return self.callback(dispatcher.bot, update, **optional_args)
TypeError: talk_to_me() got an unexpected keyword argument 'update_queue'
2019-12-02 02:08:33,617 - INFO - Received signal 2 (SIGINT), stopping...
2019-12-02 23:54:00,246 - INFO - Бот запускается
2019-12-02 23:54:01,870 - ERROR - No error handlers are registered, logging exception.
Traceback (most recent call last):
  File "C:\Users\User\AppData\Local\Programs\Python\Python37\lib\site-packages\telegram\ext\dispatcher.py", line 372, in process_update
    handler.handle_update(update, self, check, context)
  File "C:\Users\User\AppData\Local\Programs\Python\Python37\lib\site-packages\telegram\ext\handler.py", line 120, in handle_update
    return self.callback(dispatcher.bot, update, **optional_args)
TypeError: talk_to_me() got an unexpected keyword argument 'update_queue'
2019-12-02 23:54:17,943 - ERROR - No error handlers are registered, logging exception.
Traceback (most recent call last):
  File "C:\Users\User\AppData\Local\Programs\Python\Python37\lib\site-packages\telegram\ext\dispatcher.py", line 372, in process_update
    handler.handle_update(update, self, check, context)
  File "C:\Users\User\AppData\Local\Programs\Python\Python37\lib\site-packages\telegram\ext\handler.py", line 120, in handle_update
    return self.callback(dispatcher.bot, update, **optional_args)
  File "C:\projects\lesson1\vitaliybot\bot.py", line 29, in planet
    planet_user_whant = update.message.text.split()[1]
AttributeError: 'NoneType' object has no attribute 'text'
2019-12-02 23:54:45,894 - ERROR - No error handlers are registered, logging exception.
Traceback (most recent call last):
  File "C:\Users\User\AppData\Local\Programs\Python\Python37\lib\site-packages\telegram\ext\dispatcher.py", line 372, in process_update
    handler.handle_update(update, self, check, context)
  File "C:\Users\User\AppData\Local\Programs\Python\Python37\lib\site-packages\telegram\ext\handler.py", line 120, in handle_update
    return self.callback(dispatcher.bot, update, **optional_args)
  File "C:\projects\lesson1\vitaliybot\bot.py", line 30, in planet
    planet_name = planets_dict[planet_user_whant]
KeyError: 'Где'
2019-12-02 23:55:35,777 - INFO - Received signal 2 (SIGINT), stopping...
2019-12-03 00:06:18,800 - INFO - Бот запускается
2019-12-03 00:07:44,324 - INFO - Received signal 2 (SIGINT), stopping...
2019-12-03 00:07:53,199 - INFO - Бот запускается
2019-12-03 00:08:56,252 - INFO - Received signal 2 (SIGINT), stopping...
2019-12-03 00:09:03,152 - INFO - Бот запускается
2019-12-03 00:09:20,236 - ERROR - No error handlers are registered, logging exception.
Traceback (most recent call last):
  File "C:\Users\User\AppData\Local\Programs\Python\Python37\lib\site-packages\telegram\ext\dispatcher.py", line 372, in process_update
    handler.handle_update(update, self, check, context)
  File "C:\Users\User\AppData\Local\Programs\Python\Python37\lib\site-packages\telegram\ext\handler.py", line 120, in handle_update
    return self.callback(dispatcher.bot, update, **optional_args)
  File "C:\projects\lesson1\vitaliybot\bot.py", line 30, in planet
    planet_name = planets_dict[planet_user_whant]
KeyError: 'Нигде'
2019-12-03 00:10:57,850 - INFO - Received signal 2 (SIGINT), stopping...
2019-12-03 00:11:03,122 - INFO - Бот запускается
2019-12-03 00:11:42,396 - INFO - Received signal 2 (SIGINT), stopping...
2019-12-03 00:11:48,773 - INFO - Бот запускается
2019-12-03 00:12:01,225 - ERROR - No error handlers are registered, logging exception.
Traceback (most recent call last):
  File "C:\Users\User\AppData\Local\Programs\Python\Python37\lib\site-packages\telegram\ext\dispatcher.py", line 372, in process_update
    handler.handle_update(update, self, check, context)
  File "C:\Users\User\AppData\Local\Programs\Python\Python37\lib\site-packages\telegram\ext\handler.py", line 120, in handle_update
    return self.callback(dispatcher.bot, update, **optional_args)
  File "C:\projects\lesson1\vitaliybot\bot.py", line 30, in planet
    planet_name = planets_dict[planet_user_whant]
KeyError: 'Нигде'
2019-12-03 00:12:37,637 - INFO - Received signal 2 (SIGINT), stopping...
2019-12-03 00:12:43,282 - INFO - Бот запускается
2019-12-03 00:12:48,807 - ERROR - No error handlers are registered, logging exception.
Traceback (most recent call last):
  File "C:\Users\User\AppData\Local\Programs\Python\Python37\lib\site-packages\telegram\ext\dispatcher.py", line 372, in process_update
    handler.handle_update(update, self, check, context)
  File "C:\Users\User\AppData\Local\Programs\Python\Python37\lib\site-packages\telegram\ext\handler.py", line 120, in handle_update
    return self.callback(dispatcher.bot, update, **optional_args)
  File "C:\projects\lesson1\vitaliybot\bot.py", line 30, in planet
    planet_name = planets_dict[planet_user_whant]
KeyError: 'Нигде'
2019-12-03 00:16:49,338 - INFO - Received signal 2 (SIGINT), stopping...
2019-12-03 00:16:51,995 - INFO - Бот запускается
2019-12-03 00:17:00,227 - ERROR - No error handlers are registered, logging exception.
Traceback (most recent call last):
  File "C:\Users\User\AppData\Local\Programs\Python\Python37\lib\site-packages\telegram\ext\dispatcher.py", line 372, in process_update
    handler.handle_update(update, self, check, context)
  File "C:\Users\User\AppData\Local\Programs\Python\Python37\lib\site-packages\telegram\ext\handler.py", line 120, in handle_update
    return self.callback(dispatcher.bot, update, **optional_args)
  File "C:\projects\lesson1\vitaliybot\bot.py", line 30, in planet
    planet_name = planets_dict[planet_user_whant]
KeyError: 'Нигде'
2019-12-03 00:17:17,677 - ERROR - No error handlers are registered, logging exception.
Traceback (most recent call last):
  File "C:\Users\User\AppData\Local\Programs\Python\Python37\lib\site-packages\telegram\ext\dispatcher.py", line 372, in process_update
    handler.handle_update(update, self, check, context)
  File "C:\Users\User\AppData\Local\Programs\Python\Python37\lib\site-packages\telegram\ext\handler.py", line 120, in handle_update
    return self.callback(dispatcher.bot, update, **optional_args)
  File "C:\projects\lesson1\vitaliybot\bot.py", line 30, in planet
    planet_name = planets_dict[planet_user_whant]
KeyError: 'эээээ'
2019-12-03 00:17:30,117 - INFO - Received signal 2 (SIGINT), stopping...
2019-12-03 00:24:52,541 - INFO - Бот запускается
2019-12-03 00:24:57,471 - ERROR - No error handlers are registered, logging exception.
Traceback (most recent call last):
  File "C:\Users\User\AppData\Local\Programs\Python\Python37\lib\site-packages\telegram\ext\dispatcher.py", line 372, in process_update
    handler.handle_update(update, self, check, context)
  File "C:\Users\User\AppData\Local\Programs\Python\Python37\lib\site-packages\telegram\ext\handler.py", line 120, in handle_update
    return self.callback(dispatcher.bot, update, **optional_args)
  File "C:\projects\lesson1\vitaliybot\bot.py", line 33, in planet
    if  planet_name in True:
TypeError: argument of type 'bool' is not iterable
2019-12-03 00:25:01,655 - ERROR - No error handlers are registered, logging exception.
Traceback (most recent call last):
  File "C:\Users\User\AppData\Local\Programs\Python\Python37\lib\site-packages\telegram\ext\dispatcher.py", line 372, in process_update
    handler.handle_update(update, self, check, context)
  File "C:\Users\User\AppData\Local\Programs\Python\Python37\lib\site-packages\telegram\ext\handler.py", line 120, in handle_update
    return self.callback(dispatcher.bot, update, **optional_args)
  File "C:\projects\lesson1\vitaliybot\bot.py", line 30, in planet
    planet_name = planets_dict[planet_user_whant]
KeyError: 'эээээ'
2019-12-03 00:25:25,542 - INFO - Received signal 2 (SIGINT), stopping...
2019-12-03 00:25:33,582 - INFO - Бот запускается
2019-12-03 00:25:36,638 - ERROR - No error handlers are registered, logging exception.
Traceback (most recent call last):
  File "C:\Users\User\AppData\Local\Programs\Python\Python37\lib\site-packages\telegram\ext\dispatcher.py", line 372, in process_update
    handler.handle_update(update, self, check, context)
  File "C:\Users\User\AppData\Local\Programs\Python\Python37\lib\site-packages\telegram\ext\handler.py", line 120, in handle_update
    return self.callback(dispatcher.bot, update, **optional_args)
  File "C:\projects\lesson1\vitaliybot\bot.py", line 30, in planet
    planet_name = planets_dict[planet_user_whant]
KeyError: 'эээээ'
2019-12-03 00:25:45,968 - ERROR - No error handlers are registered, logging exception.
Traceback (most recent call last):
  File "C:\Users\User\AppData\Local\Programs\Python\Python37\lib\site-packages\telegram\ext\dispatcher.py", line 372, in process_update
    handler.handle_update(update, self, check, context)
  File "C:\Users\User\AppData\Local\Programs\Python\Python37\lib\site-packages\telegram\ext\handler.py", line 120, in handle_update
    return self.callback(dispatcher.bot, update, **optional_args)
  File "C:\projects\lesson1\vitaliybot\bot.py", line 30, in planet
    planet_name = planets_dict[planet_user_whant]
KeyError: 'эээээ'
2019-12-03 00:26:05,534 - INFO - Received signal 2 (SIGINT), stopping...
2019-12-03 00:26:08,019 - INFO - Бот запускается
2019-12-03 00:26:10,751 - ERROR - No error handlers are registered, logging exception.
Traceback (most recent call last):
  File "C:\Users\User\AppData\Local\Programs\Python\Python37\lib\site-packages\telegram\ext\dispatcher.py", line 372, in process_update
    handler.handle_update(update, self, check, context)
  File "C:\Users\User\AppData\Local\Programs\Python\Python37\lib\site-packages\telegram\ext\handler.py", line 120, in handle_update
    return self.callback(dispatcher.bot, update, **optional_args)
  File "C:\projects\lesson1\vitaliybot\bot.py", line 30, in planet
    planet_name = planets_dict[planet_user_whant]
KeyError: 'эээээ'
2019-12-03 00:26:22,226 - ERROR - No error handlers are registered, logging exception.
Traceback (most recent call last):
  File "C:\Users\User\AppData\Local\Programs\Python\Python37\lib\site-packages\telegram\ext\dispatcher.py", line 372, in process_update
    handler.handle_update(update, self, check, context)
  File "C:\Users\User\AppData\Local\Programs\Python\Python37\lib\site-packages\telegram\ext\handler.py", line 120, in handle_update
    return self.callback(dispatcher.bot, update, **optional_args)
  File "C:\projects\lesson1\vitaliybot\bot.py", line 30, in planet
    planet_name = planets_dict[planet_user_whant]
KeyError: 'эээээ'
2019-12-03 00:28:46,999 - INFO - Received signal 2 (SIGINT), stopping...
2019-12-03 00:28:56,184 - INFO - Бот запускается
2019-12-03 00:29:01,559 - ERROR - No error handlers are registered, logging exception.
Traceback (most recent call last):
  File "C:\Users\User\AppData\Local\Programs\Python\Python37\lib\site-packages\telegram\ext\dispatcher.py", line 372, in process_update
    handler.handle_update(update, self, check, context)
  File "C:\Users\User\AppData\Local\Programs\Python\Python37\lib\site-packages\telegram\ext\handler.py", line 120, in handle_update
    return self.callback(dispatcher.bot, update, **optional_args)
  File "C:\projects\lesson1\vitaliybot\bot.py", line 30, in planet
    planet_name = planets_dict[planet_user_whant]
KeyError: 'эээээ'
2019-12-03 00:29:54,125 - INFO - Received signal 2 (SIGINT), stopping...
2019-12-03 00:29:56,892 - INFO - Бот запускается
2019-12-03 00:30:07,212 - ERROR - No error handlers are registered, logging exception.
Traceback (most recent call last):
  File "C:\Users\User\AppData\Local\Programs\Python\Python37\lib\site-packages\telegram\ext\dispatcher.py", line 372, in process_update
    handler.handle_update(update, self, check, context)
  File "C:\Users\User\AppData\Local\Programs\Python\Python37\lib\site-packages\telegram\ext\handler.py", line 120, in handle_update
    return self.callback(dispatcher.bot, update, **optional_args)
  File "C:\projects\lesson1\vitaliybot\bot.py", line 30, in planet
    planet_name = planets_dict[planet_user_whant]
KeyError: 'эээээ'
2019-12-03 22:19:48,578 - ERROR - Error while getting Updates: urllib3 HTTPError ('Connection aborted.', ConnectionResetError(10054, 'Удаленный хост принудительно разорвал существующее подключение', None, 10054, None))
2019-12-03 22:19:48,592 - ERROR - No error handlers are registered, logging exception.
Traceback (most recent call last):
  File "C:\Users\User\AppData\Local\Programs\Python\Python37\lib\site-packages\telegram\vendor\ptb_urllib3\urllib3\connectionpool.py", line 617, in urlopen
    chunked=chunked)
  File "C:\Users\User\AppData\Local\Programs\Python\Python37\lib\site-packages\telegram\vendor\ptb_urllib3\urllib3\connectionpool.py", line 402, in _make_request
    six.raise_from(e, None)
  File "<string>", line 2, in raise_from
  File "C:\Users\User\AppData\Local\Programs\Python\Python37\lib\site-packages\telegram\vendor\ptb_urllib3\urllib3\connectionpool.py", line 398, in _make_request
    httplib_response = conn.getresponse()
  File "C:\Users\User\AppData\Local\Programs\Python\Python37\lib\http\client.py", line 1344, in getresponse
    response.begin()
  File "C:\Users\User\AppData\Local\Programs\Python\Python37\lib\http\client.py", line 306, in begin
    version, status, reason = self._read_status()
  File "C:\Users\User\AppData\Local\Programs\Python\Python37\lib\http\client.py", line 267, in _read_status
    line = str(self.fp.readline(_MAXLINE + 1), "iso-8859-1")
  File "C:\Users\User\AppData\Local\Programs\Python\Python37\lib\socket.py", line 589, in readinto
    return self._sock.recv_into(b)
  File "C:\Users\User\AppData\Local\Programs\Python\Python37\lib\ssl.py", line 1071, in recv_into
    return self.read(nbytes, buffer)
  File "C:\Users\User\AppData\Local\Programs\Python\Python37\lib\ssl.py", line 929, in read
    return self._sslobj.read(len, buffer)
ConnectionResetError: [WinError 10054] Удаленный хост принудительно разорвал существующее подключение

During handling of the above exception, another exception occurred:

Traceback (most recent call last):
  File "C:\Users\User\AppData\Local\Programs\Python\Python37\lib\site-packages\telegram\utils\request.py", line 218, in _request_wrapper
    resp = self._con_pool.request(*args, **kwargs)
  File "C:\Users\User\AppData\Local\Programs\Python\Python37\lib\site-packages\telegram\vendor\ptb_urllib3\urllib3\request.py", line 70, in request
    **urlopen_kw)
  File "C:\Users\User\AppData\Local\Programs\Python\Python37\lib\site-packages\telegram\vendor\ptb_urllib3\urllib3\request.py", line 148, in request_encode_body
    return self.urlopen(method, url, **extra_kw)
  File "C:\Users\User\AppData\Local\Programs\Python\Python37\lib\site-packages\telegram\vendor\ptb_urllib3\urllib3\poolmanager.py", line 244, in urlopen
    response = conn.urlopen(method, u.request_uri, **kw)
  File "C:\Users\User\AppData\Local\Programs\Python\Python37\lib\site-packages\telegram\vendor\ptb_urllib3\urllib3\connectionpool.py", line 666, in urlopen
    _stacktrace=sys.exc_info()[2])
  File "C:\Users\User\AppData\Local\Programs\Python\Python37\lib\site-packages\telegram\vendor\ptb_urllib3\urllib3\util\retry.py", line 347, in increment
    raise six.reraise(type(error), error, _stacktrace)
  File "C:\Users\User\AppData\Local\Programs\Python\Python37\lib\site-packages\telegram\vendor\ptb_urllib3\urllib3\packages\six.py", line 685, in reraise
    raise value.with_traceback(tb)
  File "C:\Users\User\AppData\Local\Programs\Python\Python37\lib\site-packages\telegram\vendor\ptb_urllib3\urllib3\connectionpool.py", line 617, in urlopen
    chunked=chunked)
  File "C:\Users\User\AppData\Local\Programs\Python\Python37\lib\site-packages\telegram\vendor\ptb_urllib3\urllib3\connectionpool.py", line 402, in _make_request
    six.raise_from(e, None)
  File "<string>", line 2, in raise_from
  File "C:\Users\User\AppData\Local\Programs\Python\Python37\lib\site-packages\telegram\vendor\ptb_urllib3\urllib3\connectionpool.py", line 398, in _make_request
    httplib_response = conn.getresponse()
  File "C:\Users\User\AppData\Local\Programs\Python\Python37\lib\http\client.py", line 1344, in getresponse
    response.begin()
  File "C:\Users\User\AppData\Local\Programs\Python\Python37\lib\http\client.py", line 306, in begin
    version, status, reason = self._read_status()
  File "C:\Users\User\AppData\Local\Programs\Python\Python37\lib\http\client.py", line 267, in _read_status
    line = str(self.fp.readline(_MAXLINE + 1), "iso-8859-1")
  File "C:\Users\User\AppData\Local\Programs\Python\Python37\lib\socket.py", line 589, in readinto
    return self._sock.recv_into(b)
  File "C:\Users\User\AppData\Local\Programs\Python\Python37\lib\ssl.py", line 1071, in recv_into
    return self.read(nbytes, buffer)
  File "C:\Users\User\AppData\Local\Programs\Python\Python37\lib\ssl.py", line 929, in read
    return self._sslobj.read(len, buffer)
telegram.vendor.ptb_urllib3.urllib3.exceptions.ProtocolError: ('Connection aborted.', ConnectionResetError(10054, 'Удаленный хост принудительно разорвал существующее подключение', None, 10054, None))

During handling of the above exception, another exception occurred:

Traceback (most recent call last):
  File "C:\Users\User\AppData\Local\Programs\Python\Python37\lib\site-packages\telegram\ext\updater.py", line 332, in _network_loop_retry
    if not action_cb():
  File "C:\Users\User\AppData\Local\Programs\Python\Python37\lib\site-packages\telegram\ext\updater.py", line 293, in polling_action_cb
    allowed_updates=allowed_updates)
  File "C:\Users\User\AppData\Local\Programs\Python\Python37\lib\site-packages\telegram\bot.py", line 66, in decorator
    result = func(self, *args, **kwargs)
  File "C:\Users\User\AppData\Local\Programs\Python\Python37\lib\site-packages\telegram\bot.py", line 1983, in get_updates
    result = self._request.post(url, data, timeout=float(read_latency) + float(timeout))
  File "C:\Users\User\AppData\Local\Programs\Python\Python37\lib\site-packages\telegram\utils\request.py", line 327, in post
    **urlopen_kwargs)
  File "C:\Users\User\AppData\Local\Programs\Python\Python37\lib\site-packages\telegram\utils\request.py", line 224, in _request_wrapper
    raise NetworkError('urllib3 HTTPError {0}'.format(error))
telegram.error.NetworkError: urllib3 HTTPError ('Connection aborted.', ConnectionResetError(10054, 'Удаленный хост принудительно разорвал существующее подключение', None, 10054, None))
2019-12-03 22:19:49,581 - WARNING - Retrying (Retry(total=2, connect=None, read=None, redirect=None)) after connection broken by 'NewConnectionError('<telegram.vendor.ptb_urllib3.urllib3.contrib.socks.SOCKSHTTPSConnection object at 0x000002AEEA1C6248>: Failed to establish a new connection: [Errno 11001] getaddrinfo failed')': /bot1022326450:AAFWDVOp2PLin8UUenv61C6qZpHfTrYkMD8/getUpdates
2019-12-03 22:19:49,610 - WARNING - Retrying (Retry(total=1, connect=None, read=None, redirect=None)) after connection broken by 'NewConnectionError('<telegram.vendor.ptb_urllib3.urllib3.contrib.socks.SOCKSHTTPSConnection object at 0x000002AEEAACA208>: Failed to establish a new connection: [Errno 11001] getaddrinfo failed')': /bot1022326450:AAFWDVOp2PLin8UUenv61C6qZpHfTrYkMD8/getUpdates
2019-12-03 22:19:49,643 - WARNING - Retrying (Retry(total=0, connect=None, read=None, redirect=None)) after connection broken by 'NewConnectionError('<telegram.vendor.ptb_urllib3.urllib3.contrib.socks.SOCKSHTTPSConnection object at 0x000002AEEAACA388>: Failed to establish a new connection: [Errno 11001] getaddrinfo failed')': /bot1022326450:AAFWDVOp2PLin8UUenv61C6qZpHfTrYkMD8/getUpdates
2019-12-03 22:19:49,644 - ERROR - Error while getting Updates: urllib3 HTTPError SOCKSHTTPSConnectionPool(host='api.telegram.org', port=443): Max retries exceeded with url: /bot1022326450:AAFWDVOp2PLin8UUenv61C6qZpHfTrYkMD8/getUpdates (Caused by NewConnectionError('<telegram.vendor.ptb_urllib3.urllib3.contrib.socks.SOCKSHTTPSConnection object at 0x000002AEEAACA788>: Failed to establish a new connection: [Errno 11001] getaddrinfo failed'))
2019-12-03 22:19:49,645 - ERROR - No error handlers are registered, logging exception.
Traceback (most recent call last):
  File "C:\Users\User\AppData\Local\Programs\Python\Python37\lib\site-packages\telegram\vendor\ptb_urllib3\urllib3\contrib\socks.py", line 88, in _new_conn
    **extra_kw
  File "C:\Users\User\AppData\Local\Programs\Python\Python37\lib\site-packages\socks.py", line 180, in create_connection
    for r in socket.getaddrinfo(proxy_addr, proxy_port, 0, socket.SOCK_STREAM):
  File "C:\Users\User\AppData\Local\Programs\Python\Python37\lib\socket.py", line 748, in getaddrinfo
    for res in _socket.getaddrinfo(host, port, family, type, proto, flags):
socket.gaierror: [Errno 11001] getaddrinfo failed

During handling of the above exception, another exception occurred:

Traceback (most recent call last):
  File "C:\Users\User\AppData\Local\Programs\Python\Python37\lib\site-packages\telegram\vendor\ptb_urllib3\urllib3\connectionpool.py", line 617, in urlopen
    chunked=chunked)
  File "C:\Users\User\AppData\Local\Programs\Python\Python37\lib\site-packages\telegram\vendor\ptb_urllib3\urllib3\connectionpool.py", line 360, in _make_request
    self._validate_conn(conn)
  File "C:\Users\User\AppData\Local\Programs\Python\Python37\lib\site-packages\telegram\vendor\ptb_urllib3\urllib3\connectionpool.py", line 857, in _validate_conn
    super(HTTPSConnectionPool, self)._validate_conn(conn)
  File "C:\Users\User\AppData\Local\Programs\Python\Python37\lib\site-packages\telegram\vendor\ptb_urllib3\urllib3\connectionpool.py", line 289, in _validate_conn
    conn.connect()
  File "C:\Users\User\AppData\Local\Programs\Python\Python37\lib\site-packages\telegram\vendor\ptb_urllib3\urllib3\connection.py", line 284, in connect
    conn = self._new_conn()
  File "C:\Users\User\AppData\Local\Programs\Python\Python37\lib\site-packages\telegram\vendor\ptb_urllib3\urllib3\contrib\socks.py", line 120, in _new_conn
    self, "Failed to establish a new connection: %s" % e)
telegram.vendor.ptb_urllib3.urllib3.exceptions.NewConnectionError: <telegram.vendor.ptb_urllib3.urllib3.contrib.socks.SOCKSHTTPSConnection object at 0x000002AEEAACA788>: Failed to establish a new connection: [Errno 11001] getaddrinfo failed

During handling of the above exception, another exception occurred:

Traceback (most recent call last):
  File "C:\Users\User\AppData\Local\Programs\Python\Python37\lib\site-packages\telegram\utils\request.py", line 218, in _request_wrapper
    resp = self._con_pool.request(*args, **kwargs)
  File "C:\Users\User\AppData\Local\Programs\Python\Python37\lib\site-packages\telegram\vendor\ptb_urllib3\urllib3\request.py", line 70, in request
    **urlopen_kw)
  File "C:\Users\User\AppData\Local\Programs\Python\Python37\lib\site-packages\telegram\vendor\ptb_urllib3\urllib3\request.py", line 148, in request_encode_body
    return self.urlopen(method, url, **extra_kw)
  File "C:\Users\User\AppData\Local\Programs\Python\Python37\lib\site-packages\telegram\vendor\ptb_urllib3\urllib3\poolmanager.py", line 244, in urlopen
    response = conn.urlopen(method, u.request_uri, **kw)
  File "C:\Users\User\AppData\Local\Programs\Python\Python37\lib\site-packages\telegram\vendor\ptb_urllib3\urllib3\connectionpool.py", line 695, in urlopen
    **response_kw)
  File "C:\Users\User\AppData\Local\Programs\Python\Python37\lib\site-packages\telegram\vendor\ptb_urllib3\urllib3\connectionpool.py", line 695, in urlopen
    **response_kw)
  File "C:\Users\User\AppData\Local\Programs\Python\Python37\lib\site-packages\telegram\vendor\ptb_urllib3\urllib3\connectionpool.py", line 695, in urlopen
    **response_kw)
  File "C:\Users\User\AppData\Local\Programs\Python\Python37\lib\site-packages\telegram\vendor\ptb_urllib3\urllib3\connectionpool.py", line 666, in urlopen
    _stacktrace=sys.exc_info()[2])
  File "C:\Users\User\AppData\Local\Programs\Python\Python37\lib\site-packages\telegram\vendor\ptb_urllib3\urllib3\util\retry.py", line 376, in increment
    raise MaxRetryError(_pool, url, error or ResponseError(cause))
telegram.vendor.ptb_urllib3.urllib3.exceptions.MaxRetryError: SOCKSHTTPSConnectionPool(host='api.telegram.org', port=443): Max retries exceeded with url: /bot1022326450:AAFWDVOp2PLin8UUenv61C6qZpHfTrYkMD8/getUpdates (Caused by NewConnectionError('<telegram.vendor.ptb_urllib3.urllib3.contrib.socks.SOCKSHTTPSConnection object at 0x000002AEEAACA788>: Failed to establish a new connection: [Errno 11001] getaddrinfo failed'))

During handling of the above exception, another exception occurred:

Traceback (most recent call last):
  File "C:\Users\User\AppData\Local\Programs\Python\Python37\lib\site-packages\telegram\ext\updater.py", line 332, in _network_loop_retry
    if not action_cb():
  File "C:\Users\User\AppData\Local\Programs\Python\Python37\lib\site-packages\telegram\ext\updater.py", line 293, in polling_action_cb
    allowed_updates=allowed_updates)
  File "C:\Users\User\AppData\Local\Programs\Python\Python37\lib\site-packages\telegram\bot.py", line 66, in decorator
    result = func(self, *args, **kwargs)
  File "C:\Users\User\AppData\Local\Programs\Python\Python37\lib\site-packages\telegram\bot.py", line 1983, in get_updates
    result = self._request.post(url, data, timeout=float(read_latency) + float(timeout))
  File "C:\Users\User\AppData\Local\Programs\Python\Python37\lib\site-packages\telegram\utils\request.py", line 327, in post
    **urlopen_kwargs)
  File "C:\Users\User\AppData\Local\Programs\Python\Python37\lib\site-packages\telegram\utils\request.py", line 224, in _request_wrapper
    raise NetworkError('urllib3 HTTPError {0}'.format(error))
telegram.error.NetworkError: urllib3 HTTPError SOCKSHTTPSConnectionPool(host='api.telegram.org', port=443): Max retries exceeded with url: /bot1022326450:AAFWDVOp2PLin8UUenv61C6qZpHfTrYkMD8/getUpdates (Caused by NewConnectionError('<telegram.vendor.ptb_urllib3.urllib3.contrib.socks.SOCKSHTTPSConnection object at 0x000002AEEAACA788>: Failed to establish a new connection: [Errno 11001] getaddrinfo failed'))
2019-12-03 22:19:51,147 - WARNING - Retrying (Retry(total=2, connect=None, read=None, redirect=None)) after connection broken by 'NewConnectionError('<telegram.vendor.ptb_urllib3.urllib3.contrib.socks.SOCKSHTTPSConnection object at 0x000002AEEAA38A48>: Failed to establish a new connection: [Errno 11001] getaddrinfo failed')': /bot1022326450:AAFWDVOp2PLin8UUenv61C6qZpHfTrYkMD8/getUpdates
2019-12-03 22:19:51,147 - WARNING - Retrying (Retry(total=1, connect=None, read=None, redirect=None)) after connection broken by 'NewConnectionError('<telegram.vendor.ptb_urllib3.urllib3.contrib.socks.SOCKSHTTPSConnection object at 0x000002AEEAAED148>: Failed to establish a new connection: [Errno 11001] getaddrinfo failed')': /bot1022326450:AAFWDVOp2PLin8UUenv61C6qZpHfTrYkMD8/getUpdates
2019-12-03 22:19:51,149 - WARNING - Retrying (Retry(total=0, connect=None, read=None, redirect=None)) after connection broken by 'NewConnectionError('<telegram.vendor.ptb_urllib3.urllib3.contrib.socks.SOCKSHTTPSConnection object at 0x000002AEEAAED2C8>: Failed to establish a new connection: [Errno 11001] getaddrinfo failed')': /bot1022326450:AAFWDVOp2PLin8UUenv61C6qZpHfTrYkMD8/getUpdates
2019-12-03 22:19:51,151 - ERROR - Error while getting Updates: urllib3 HTTPError SOCKSHTTPSConnectionPool(host='api.telegram.org', port=443): Max retries exceeded with url: /bot1022326450:AAFWDVOp2PLin8UUenv61C6qZpHfTrYkMD8/getUpdates (Caused by NewConnectionError('<telegram.vendor.ptb_urllib3.urllib3.contrib.socks.SOCKSHTTPSConnection object at 0x000002AEEAAED6C8>: Failed to establish a new connection: [Errno 11001] getaddrinfo failed'))
2019-12-03 22:19:51,151 - ERROR - No error handlers are registered, logging exception.
Traceback (most recent call last):
  File "C:\Users\User\AppData\Local\Programs\Python\Python37\lib\site-packages\telegram\vendor\ptb_urllib3\urllib3\contrib\socks.py", line 88, in _new_conn
    **extra_kw
  File "C:\Users\User\AppData\Local\Programs\Python\Python37\lib\site-packages\socks.py", line 180, in create_connection
    for r in socket.getaddrinfo(proxy_addr, proxy_port, 0, socket.SOCK_STREAM):
  File "C:\Users\User\AppData\Local\Programs\Python\Python37\lib\socket.py", line 748, in getaddrinfo
    for res in _socket.getaddrinfo(host, port, family, type, proto, flags):
socket.gaierror: [Errno 11001] getaddrinfo failed

During handling of the above exception, another exception occurred:

Traceback (most recent call last):
  File "C:\Users\User\AppData\Local\Programs\Python\Python37\lib\site-packages\telegram\vendor\ptb_urllib3\urllib3\connectionpool.py", line 617, in urlopen
    chunked=chunked)
  File "C:\Users\User\AppData\Local\Programs\Python\Python37\lib\site-packages\telegram\vendor\ptb_urllib3\urllib3\connectionpool.py", line 360, in _make_request
    self._validate_conn(conn)
  File "C:\Users\User\AppData\Local\Programs\Python\Python37\lib\site-packages\telegram\vendor\ptb_urllib3\urllib3\connectionpool.py", line 857, in _validate_conn
    super(HTTPSConnectionPool, self)._validate_conn(conn)
  File "C:\Users\User\AppData\Local\Programs\Python\Python37\lib\site-packages\telegram\vendor\ptb_urllib3\urllib3\connectionpool.py", line 289, in _validate_conn
    conn.connect()
  File "C:\Users\User\AppData\Local\Programs\Python\Python37\lib\site-packages\telegram\vendor\ptb_urllib3\urllib3\connection.py", line 284, in connect
    conn = self._new_conn()
  File "C:\Users\User\AppData\Local\Programs\Python\Python37\lib\site-packages\telegram\vendor\ptb_urllib3\urllib3\contrib\socks.py", line 120, in _new_conn
    self, "Failed to establish a new connection: %s" % e)
telegram.vendor.ptb_urllib3.urllib3.exceptions.NewConnectionError: <telegram.vendor.ptb_urllib3.urllib3.contrib.socks.SOCKSHTTPSConnection object at 0x000002AEEAAED6C8>: Failed to establish a new connection: [Errno 11001] getaddrinfo failed

During handling of the above exception, another exception occurred:

Traceback (most recent call last):
  File "C:\Users\User\AppData\Local\Programs\Python\Python37\lib\site-packages\telegram\utils\request.py", line 218, in _request_wrapper
    resp = self._con_pool.request(*args, **kwargs)
  File "C:\Users\User\AppData\Local\Programs\Python\Python37\lib\site-packages\telegram\vendor\ptb_urllib3\urllib3\request.py", line 70, in request
    **urlopen_kw)
  File "C:\Users\User\AppData\Local\Programs\Python\Python37\lib\site-packages\telegram\vendor\ptb_urllib3\urllib3\request.py", line 148, in request_encode_body
    return self.urlopen(method, url, **extra_kw)
  File "C:\Users\User\AppData\Local\Programs\Python\Python37\lib\site-packages\telegram\vendor\ptb_urllib3\urllib3\poolmanager.py", line 244, in urlopen
    response = conn.urlopen(method, u.request_uri, **kw)
  File "C:\Users\User\AppData\Local\Programs\Python\Python37\lib\site-packages\telegram\vendor\ptb_urllib3\urllib3\connectionpool.py", line 695, in urlopen
    **response_kw)
  File "C:\Users\User\AppData\Local\Programs\Python\Python37\lib\site-packages\telegram\vendor\ptb_urllib3\urllib3\connectionpool.py", line 695, in urlopen
    **response_kw)
  File "C:\Users\User\AppData\Local\Programs\Python\Python37\lib\site-packages\telegram\vendor\ptb_urllib3\urllib3\connectionpool.py", line 695, in urlopen
    **response_kw)
  File "C:\Users\User\AppData\Local\Programs\Python\Python37\lib\site-packages\telegram\vendor\ptb_urllib3\urllib3\connectionpool.py", line 666, in urlopen
    _stacktrace=sys.exc_info()[2])
  File "C:\Users\User\AppData\Local\Programs\Python\Python37\lib\site-packages\telegram\vendor\ptb_urllib3\urllib3\util\retry.py", line 376, in increment
    raise MaxRetryError(_pool, url, error or ResponseError(cause))
telegram.vendor.ptb_urllib3.urllib3.exceptions.MaxRetryError: SOCKSHTTPSConnectionPool(host='api.telegram.org', port=443): Max retries exceeded with url: /bot1022326450:AAFWDVOp2PLin8UUenv61C6qZpHfTrYkMD8/getUpdates (Caused by NewConnectionError('<telegram.vendor.ptb_urllib3.urllib3.contrib.socks.SOCKSHTTPSConnection object at 0x000002AEEAAED6C8>: Failed to establish a new connection: [Errno 11001] getaddrinfo failed'))

During handling of the above exception, another exception occurred:

Traceback (most recent call last):
  File "C:\Users\User\AppData\Local\Programs\Python\Python37\lib\site-packages\telegram\ext\updater.py", line 332, in _network_loop_retry
    if not action_cb():
  File "C:\Users\User\AppData\Local\Programs\Python\Python37\lib\site-packages\telegram\ext\updater.py", line 293, in polling_action_cb
    allowed_updates=allowed_updates)
  File "C:\Users\User\AppData\Local\Programs\Python\Python37\lib\site-packages\telegram\bot.py", line 66, in decorator
    result = func(self, *args, **kwargs)
  File "C:\Users\User\AppData\Local\Programs\Python\Python37\lib\site-packages\telegram\bot.py", line 1983, in get_updates
    result = self._request.post(url, data, timeout=float(read_latency) + float(timeout))
  File "C:\Users\User\AppData\Local\Programs\Python\Python37\lib\site-packages\telegram\utils\request.py", line 327, in post
    **urlopen_kwargs)
  File "C:\Users\User\AppData\Local\Programs\Python\Python37\lib\site-packages\telegram\utils\request.py", line 224, in _request_wrapper
    raise NetworkError('urllib3 HTTPError {0}'.format(error))
telegram.error.NetworkError: urllib3 HTTPError SOCKSHTTPSConnectionPool(host='api.telegram.org', port=443): Max retries exceeded with url: /bot1022326450:AAFWDVOp2PLin8UUenv61C6qZpHfTrYkMD8/getUpdates (Caused by NewConnectionError('<telegram.vendor.ptb_urllib3.urllib3.contrib.socks.SOCKSHTTPSConnection object at 0x000002AEEAAED6C8>: Failed to establish a new connection: [Errno 11001] getaddrinfo failed'))
2019-12-03 22:19:53,402 - WARNING - Retrying (Retry(total=2, connect=None, read=None, redirect=None)) after connection broken by 'NewConnectionError('<telegram.vendor.ptb_urllib3.urllib3.contrib.socks.SOCKSHTTPSConnection object at 0x000002AEEAACAB08>: Failed to establish a new connection: [Errno 11001] getaddrinfo failed')': /bot1022326450:AAFWDVOp2PLin8UUenv61C6qZpHfTrYkMD8/getUpdates
2019-12-03 22:19:53,403 - WARNING - Retrying (Retry(total=1, connect=None, read=None, redirect=None)) after connection broken by 'NewConnectionError('<telegram.vendor.ptb_urllib3.urllib3.contrib.socks.SOCKSHTTPSConnection object at 0x000002AEEAACA1C8>: Failed to establish a new connection: [Errno 11001] getaddrinfo failed')': /bot1022326450:AAFWDVOp2PLin8UUenv61C6qZpHfTrYkMD8/getUpdates
2019-12-03 22:19:53,404 - WARNING - Retrying (Retry(total=0, connect=None, read=None, redirect=None)) after connection broken by 'NewConnectionError('<telegram.vendor.ptb_urllib3.urllib3.contrib.socks.SOCKSHTTPSConnection object at 0x000002AEEAAF2388>: Failed to establish a new connection: [Errno 11001] getaddrinfo failed')': /bot1022326450:AAFWDVOp2PLin8UUenv61C6qZpHfTrYkMD8/getUpdates
2019-12-03 22:19:53,405 - ERROR - Error while getting Updates: urllib3 HTTPError SOCKSHTTPSConnectionPool(host='api.telegram.org', port=443): Max retries exceeded with url: /bot1022326450:AAFWDVOp2PLin8UUenv61C6qZpHfTrYkMD8/getUpdates (Caused by NewConnectionError('<telegram.vendor.ptb_urllib3.urllib3.contrib.socks.SOCKSHTTPSConnection object at 0x000002AEEAAF2448>: Failed to establish a new connection: [Errno 11001] getaddrinfo failed'))
2019-12-03 22:19:53,405 - ERROR - No error handlers are registered, logging exception.
Traceback (most recent call last):
  File "C:\Users\User\AppData\Local\Programs\Python\Python37\lib\site-packages\telegram\vendor\ptb_urllib3\urllib3\contrib\socks.py", line 88, in _new_conn
    **extra_kw
  File "C:\Users\User\AppData\Local\Programs\Python\Python37\lib\site-packages\socks.py", line 180, in create_connection
    for r in socket.getaddrinfo(proxy_addr, proxy_port, 0, socket.SOCK_STREAM):
  File "C:\Users\User\AppData\Local\Programs\Python\Python37\lib\socket.py", line 748, in getaddrinfo
    for res in _socket.getaddrinfo(host, port, family, type, proto, flags):
socket.gaierror: [Errno 11001] getaddrinfo failed

During handling of the above exception, another exception occurred:

Traceback (most recent call last):
  File "C:\Users\User\AppData\Local\Programs\Python\Python37\lib\site-packages\telegram\vendor\ptb_urllib3\urllib3\connectionpool.py", line 617, in urlopen
    chunked=chunked)
  File "C:\Users\User\AppData\Local\Programs\Python\Python37\lib\site-packages\telegram\vendor\ptb_urllib3\urllib3\connectionpool.py", line 360, in _make_request
    self._validate_conn(conn)
  File "C:\Users\User\AppData\Local\Programs\Python\Python37\lib\site-packages\telegram\vendor\ptb_urllib3\urllib3\connectionpool.py", line 857, in _validate_conn
    super(HTTPSConnectionPool, self)._validate_conn(conn)
  File "C:\Users\User\AppData\Local\Programs\Python\Python37\lib\site-packages\telegram\vendor\ptb_urllib3\urllib3\connectionpool.py", line 289, in _validate_conn
    conn.connect()
  File "C:\Users\User\AppData\Local\Programs\Python\Python37\lib\site-packages\telegram\vendor\ptb_urllib3\urllib3\connection.py", line 284, in connect
    conn = self._new_conn()
  File "C:\Users\User\AppData\Local\Programs\Python\Python37\lib\site-packages\telegram\vendor\ptb_urllib3\urllib3\contrib\socks.py", line 120, in _new_conn
    self, "Failed to establish a new connection: %s" % e)
telegram.vendor.ptb_urllib3.urllib3.exceptions.NewConnectionError: <telegram.vendor.ptb_urllib3.urllib3.contrib.socks.SOCKSHTTPSConnection object at 0x000002AEEAAF2448>: Failed to establish a new connection: [Errno 11001] getaddrinfo failed

During handling of the above exception, another exception occurred:

Traceback (most recent call last):
  File "C:\Users\User\AppData\Local\Programs\Python\Python37\lib\site-packages\telegram\utils\request.py", line 218, in _request_wrapper
    resp = self._con_pool.request(*args, **kwargs)
  File "C:\Users\User\AppData\Local\Programs\Python\Python37\lib\site-packages\telegram\vendor\ptb_urllib3\urllib3\request.py", line 70, in request
    **urlopen_kw)
  File "C:\Users\User\AppData\Local\Programs\Python\Python37\lib\site-packages\telegram\vendor\ptb_urllib3\urllib3\request.py", line 148, in request_encode_body
    return self.urlopen(method, url, **extra_kw)
  File "C:\Users\User\AppData\Local\Programs\Python\Python37\lib\site-packages\telegram\vendor\ptb_urllib3\urllib3\poolmanager.py", line 244, in urlopen
    response = conn.urlopen(method, u.request_uri, **kw)
  File "C:\Users\User\AppData\Local\Programs\Python\Python37\lib\site-packages\telegram\vendor\ptb_urllib3\urllib3\connectionpool.py", line 695, in urlopen
    **response_kw)
  File "C:\Users\User\AppData\Local\Programs\Python\Python37\lib\site-packages\telegram\vendor\ptb_urllib3\urllib3\connectionpool.py", line 695, in urlopen
    **response_kw)
  File "C:\Users\User\AppData\Local\Programs\Python\Python37\lib\site-packages\telegram\vendor\ptb_urllib3\urllib3\connectionpool.py", line 695, in urlopen
    **response_kw)
  File "C:\Users\User\AppData\Local\Programs\Python\Python37\lib\site-packages\telegram\vendor\ptb_urllib3\urllib3\connectionpool.py", line 666, in urlopen
    _stacktrace=sys.exc_info()[2])
  File "C:\Users\User\AppData\Local\Programs\Python\Python37\lib\site-packages\telegram\vendor\ptb_urllib3\urllib3\util\retry.py", line 376, in increment
    raise MaxRetryError(_pool, url, error or ResponseError(cause))
telegram.vendor.ptb_urllib3.urllib3.exceptions.MaxRetryError: SOCKSHTTPSConnectionPool(host='api.telegram.org', port=443): Max retries exceeded with url: /bot1022326450:AAFWDVOp2PLin8UUenv61C6qZpHfTrYkMD8/getUpdates (Caused by NewConnectionError('<telegram.vendor.ptb_urllib3.urllib3.contrib.socks.SOCKSHTTPSConnection object at 0x000002AEEAAF2448>: Failed to establish a new connection: [Errno 11001] getaddrinfo failed'))

During handling of the above exception, another exception occurred:

Traceback (most recent call last):
  File "C:\Users\User\AppData\Local\Programs\Python\Python37\lib\site-packages\telegram\ext\updater.py", line 332, in _network_loop_retry
    if not action_cb():
  File "C:\Users\User\AppData\Local\Programs\Python\Python37\lib\site-packages\telegram\ext\updater.py", line 293, in polling_action_cb
    allowed_updates=allowed_updates)
  File "C:\Users\User\AppData\Local\Programs\Python\Python37\lib\site-packages\telegram\bot.py", line 66, in decorator
    result = func(self, *args, **kwargs)
  File "C:\Users\User\AppData\Local\Programs\Python\Python37\lib\site-packages\telegram\bot.py", line 1983, in get_updates
    result = self._request.post(url, data, timeout=float(read_latency) + float(timeout))
  File "C:\Users\User\AppData\Local\Programs\Python\Python37\lib\site-packages\telegram\utils\request.py", line 327, in post
    **urlopen_kwargs)
  File "C:\Users\User\AppData\Local\Programs\Python\Python37\lib\site-packages\telegram\utils\request.py", line 224, in _request_wrapper
    raise NetworkError('urllib3 HTTPError {0}'.format(error))
telegram.error.NetworkError: urllib3 HTTPError SOCKSHTTPSConnectionPool(host='api.telegram.org', port=443): Max retries exceeded with url: /bot1022326450:AAFWDVOp2PLin8UUenv61C6qZpHfTrYkMD8/getUpdates (Caused by NewConnectionError('<telegram.vendor.ptb_urllib3.urllib3.contrib.socks.SOCKSHTTPSConnection object at 0x000002AEEAAF2448>: Failed to establish a new connection: [Errno 11001] getaddrinfo failed'))
2019-12-03 22:39:09,767 - INFO - Received signal 2 (SIGINT), stopping...
2019-12-03 22:39:17,468 - WARNING - Exiting immediately!
2019-12-03 22:39:34,151 - INFO - Бот запускается
2019-12-03 22:40:10,153 - INFO - Received signal 2 (SIGINT), stopping...
2019-12-03 22:40:20,905 - INFO - Бот запускается
2019-12-03 22:41:10,693 - INFO - Received signal 2 (SIGINT), stopping...
2019-12-03 22:44:34,569 - INFO - Бот запускается
2019-12-03 22:44:48,197 - ERROR - No error handlers are registered, logging exception.
Traceback (most recent call last):
  File "C:\Users\User\AppData\Local\Programs\Python\Python37\lib\site-packages\telegram\ext\dispatcher.py", line 372, in process_update
    handler.handle_update(update, self, check, context)
  File "C:\Users\User\AppData\Local\Programs\Python\Python37\lib\site-packages\telegram\ext\handler.py", line 120, in handle_update
    return self.callback(dispatcher.bot, update, **optional_args)
  File "C:\projects\lesson1\vitaliybot\bot.py", line 30, in planet
    planet_name = planets_dict[planet_user_whant] #Переменная = содержимое словаря ephem
KeyError: 'эээээ'
2019-12-03 22:47:38,757 - INFO - Received signal 2 (SIGINT), stopping...
2019-12-03 22:47:42,757 - INFO - Бот запускается
2019-12-03 22:47:53,081 - ERROR - No error handlers are registered, logging exception.
Traceback (most recent call last):
  File "C:\Users\User\AppData\Local\Programs\Python\Python37\lib\site-packages\telegram\ext\dispatcher.py", line 372, in process_update
    handler.handle_update(update, self, check, context)
  File "C:\Users\User\AppData\Local\Programs\Python\Python37\lib\site-packages\telegram\ext\handler.py", line 120, in handle_update
    return self.callback(dispatcher.bot, update, **optional_args)
  File "C:\projects\lesson1\vitaliybot\bot.py", line 30, in planet
    planet_name = planets_dict[planet_user_whant] #Переменная = содержимое словаря ephem
KeyError: 'эээээ'
2019-12-03 23:01:35,535 - INFO - Received signal 2 (SIGINT), stopping...
